docker compose exec flask uv run python migrate_production.py --apply
=== APPLYING MIGRATIONS TO PRODUCTION ===
WARNING: This will modify your production database!
Are you sure you want to proceed? (yes/no): yes
Creating backup before migration...
sh: 1: pg_dump: not found
Applying migrations...
INFO:root:Hetzner projects initialization completed
INFO:root:Assigned 4 existing servers to Nova HR project
INFO:root:Sample project access permissions created
INFO:root:Application initialization completed
INFO  [alembic.runtime.migration] Context impl PostgresqlImpl.
INFO  [alembic.runtime.migration] Will assume transactional DDL.
INFO  [alembic.runtime.migration] Running upgrade 001 -> 002, Add server_source and client fields to HetznerServer
Traceback (most recent call last):
  File "/app/.venv/lib/python3.11/site-packages/sqlalchemy/engine/base.py", line 1967, in _exec_single_context
    self.dialect.do_execute(
  File "/app/.venv/lib/python3.11/site-packages/sqlalchemy/engine/default.py", line 951, in do_execute
    cursor.execute(statement, parameters)
psycopg2.errors.InFailedSqlTransaction: current transaction is aborted, commands ignored until end of transaction block


The above exception was the direct cause of the following exception:

Traceback (most recent call last):
  File "/app/.venv/bin/flask", line 10, in <module>
    sys.exit(main())
             ^^^^^^
  File "/app/.venv/lib/python3.11/site-packages/flask/cli.py", line 1131, in main
    cli.main()
  File "/app/.venv/lib/python3.11/site-packages/click/core.py", line 1363, in main
    rv = self.invoke(ctx)
         ^^^^^^^^^^^^^^^^
  File "/app/.venv/lib/python3.11/site-packages/click/core.py", line 1830, in invoke
    return _process_result(sub_ctx.command.invoke(sub_ctx))
                           ^^^^^^^^^^^^^^^^^^^^^^^^^^^^^^^
  File "/app/.venv/lib/python3.11/site-packages/click/core.py", line 1830, in invoke
    return _process_result(sub_ctx.command.invoke(sub_ctx))
                           ^^^^^^^^^^^^^^^^^^^^^^^^^^^^^^^
  File "/app/.venv/lib/python3.11/site-packages/click/core.py", line 1226, in invoke
    return ctx.invoke(self.callback, **ctx.params)
           ^^^^^^^^^^^^^^^^^^^^^^^^^^^^^^^^^^^^^^^
  File "/app/.venv/lib/python3.11/site-packages/click/core.py", line 794, in invoke
    return callback(*args, **kwargs)
           ^^^^^^^^^^^^^^^^^^^^^^^^^
  File "/app/.venv/lib/python3.11/site-packages/click/decorators.py", line 34, in new_func
    return f(get_current_context(), *args, **kwargs)
           ^^^^^^^^^^^^^^^^^^^^^^^^^^^^^^^^^^^^^^^^^
  File "/app/.venv/lib/python3.11/site-packages/flask/cli.py", line 400, in decorator
    return ctx.invoke(f, *args, **kwargs)
           ^^^^^^^^^^^^^^^^^^^^^^^^^^^^^^
  File "/app/.venv/lib/python3.11/site-packages/click/core.py", line 794, in invoke
    return callback(*args, **kwargs)
           ^^^^^^^^^^^^^^^^^^^^^^^^^
  File "/app/.venv/lib/python3.11/site-packages/flask_migrate/cli.py", line 157, in upgrade
    _upgrade(directory or g.directory, revision, sql, tag, x_arg or g.x_arg)
  File "/app/.venv/lib/python3.11/site-packages/flask_migrate/__init__.py", line 111, in wrapped
    f(*args, **kwargs)
  File "/app/.venv/lib/python3.11/site-packages/flask_migrate/__init__.py", line 200, in upgrade
    command.upgrade(config, revision, sql=sql, tag=tag)
  File "/app/.venv/lib/python3.11/site-packages/alembic/command.py", line 483, in upgrade
    script.run_env()
  File "/app/.venv/lib/python3.11/site-packages/alembic/script/base.py", line 549, in run_env
    util.load_python_file(self.dir, "env.py")
  File "/app/.venv/lib/python3.11/site-packages/alembic/util/pyfiles.py", line 116, in load_python_file
    module = load_module_py(module_id, path)
             ^^^^^^^^^^^^^^^^^^^^^^^^^^^^^^^
  File "/app/.venv/lib/python3.11/site-packages/alembic/util/pyfiles.py", line 136, in load_module_py
    spec.loader.exec_module(module)  # type: ignore
    ^^^^^^^^^^^^^^^^^^^^^^^^^^^^^^^
  File "<frozen importlib._bootstrap_external>", line 940, in exec_module
  File "<frozen importlib._bootstrap>", line 241, in _call_with_frames_removed
  File "/app/migrations/env.py", line 113, in <module>
    run_migrations_online()
  File "/app/migrations/env.py", line 107, in run_migrations_online
    context.run_migrations()
  File "<string>", line 8, in run_migrations
  File "/app/.venv/lib/python3.11/site-packages/alembic/runtime/environment.py", line 946, in run_migrations
    self.get_context().run_migrations(**kw)
  File "/app/.venv/lib/python3.11/site-packages/alembic/runtime/migration.py", line 634, in run_migrations
    head_maintainer.update_to_step(step)
  File "/app/.venv/lib/python3.11/site-packages/alembic/runtime/migration.py", line 866, in update_to_step
    self._update_version(from_, to_)
  File "/app/.venv/lib/python3.11/site-packages/alembic/runtime/migration.py", line 801, in _update_version
    ret = self.context.impl._exec(
          ^^^^^^^^^^^^^^^^^^^^^^^^
  File "/app/.venv/lib/python3.11/site-packages/alembic/ddl/impl.py", line 246, in _exec
    return conn.execute(construct, params)
           ^^^^^^^^^^^^^^^^^^^^^^^^^^^^^^^
  File "/app/.venv/lib/python3.11/site-packages/sqlalchemy/engine/base.py", line 1419, in execute
    return meth(
           ^^^^^
  File "/app/.venv/lib/python3.11/site-packages/sqlalchemy/sql/elements.py", line 526, in _execute_on_connection
    return connection._execute_clauseelement(
           ^^^^^^^^^^^^^^^^^^^^^^^^^^^^^^^^^^
  File "/app/.venv/lib/python3.11/site-packages/sqlalchemy/engine/base.py", line 1641, in _execute_clauseelement
    ret = self._execute_context(
          ^^^^^^^^^^^^^^^^^^^^^^
  File "/app/.venv/lib/python3.11/site-packages/sqlalchemy/engine/base.py", line 1846, in _execute_context
    return self._exec_single_context(
           ^^^^^^^^^^^^^^^^^^^^^^^^^^
  File "/app/.venv/lib/python3.11/site-packages/sqlalchemy/engine/base.py", line 1986, in _exec_single_context
    self._handle_dbapi_exception(
  File "/app/.venv/lib/python3.11/site-packages/sqlalchemy/engine/base.py", line 2355, in _handle_dbapi_exception
    raise sqlalchemy_exception.with_traceback(exc_info[2]) from e
  File "/app/.venv/lib/python3.11/site-packages/sqlalchemy/engine/base.py", line 1967, in _exec_single_context
    self.dialect.do_execute(
  File "/app/.venv/lib/python3.11/site-packages/sqlalchemy/engine/default.py", line 951, in do_execute
    cursor.execute(statement, parameters)
sqlalchemy.exc.InternalError: (psycopg2.errors.InFailedSqlTransaction) current transaction is aborted, commands ignored until end of transaction block

[SQL: UPDATE alembic_version SET version_num='002' WHERE alembic_version.version_num = '001']
(Background on this error at: https://sqlalche.me/e/20/2j85)
‚ùå Migration failed! Check the error messages above.
You may need to restore from backup if database is in inconsistent state.